Workbook
Name SegmentaciónDeDatos_Fecha: #N/A
Name SegmentaciónDeDatos_Fecha1: #N/A

Sheet Referencia
A1: Producto | B1: categoria | C1: Calsificacion | D1: Agrupacion Personalizada | F1: Categoria | G1: Clasificacion | I1: Clasificacion
A2: Asado de Tira | B2: Vacuno | C2: =IFERROR(VLOOKUP(Productos[[#This Row],[categoria]],Categoria[],2,FALSE),"INGRESA CATEGORÍA") -> Carnes | F2: Pollo | G2: Aves | I2: Aves
A3: EntraÃ±a | B3: Vacuno | C3: =IFERROR(VLOOKUP(Productos[[#This Row],[categoria]],Categoria[],2,FALSE),"INGRESA CATEGORÍA") -> Carnes | F3: Vacuno | G3: Carnes | I3: Carnes
A4: Filete | B4: Vacuno | C4: =IFERROR(VLOOKUP(Productos[[#This Row],[categoria]],Categoria[],2,FALSE),"INGRESA CATEGORÍA") -> Carnes | F4: Cerdo | G4: Carnes | I4: Pescado
A5: Flat Iron | B5: Vacuno | C5: =IFERROR(VLOOKUP(Productos[[#This Row],[categoria]],Categoria[],2,FALSE),"INGRESA CATEGORÍA") -> Carnes | F5: Pescado | G5: Pescado | I5: Mariscos
A6: Plateada | B6: Vacuno | C6: =IFERROR(VLOOKUP(Productos[[#This Row],[categoria]],Categoria[],2,FALSE),"INGRESA CATEGORÍA") -> Carnes | F6: Mariscos | G6: Mariscos | I6: Embutidos
A7: Atun Steak | B7: Pescado | C7: =IFERROR(VLOOKUP(Productos[[#This Row],[categoria]],Categoria[],2,FALSE),"INGRESA CATEGORÍA") -> Pescado | F7: Embutidos | G7: Embutidos | I7: Lacteos
A8: Salmon | B8: Pescado | C8: =IFERROR(VLOOKUP(Productos[[#This Row],[categoria]],Categoria[],2,FALSE),"INGRESA CATEGORÍA") -> Pescado | F8: Quesos | G8: Lacteos | I8: Verduras
A9: Camaron 20/30 con cascara | B9: Mariscos | C9: =IFERROR(VLOOKUP(Productos[[#This Row],[categoria]],Categoria[],2,FALSE),"INGRESA CATEGORÍA") -> Mariscos | F9: Papas | G9: Verduras | I9: Harina
A10: Locos | B10: Mariscos | C10: =IFERROR(VLOOKUP(Productos[[#This Row],[categoria]],Categoria[],2,FALSE),"INGRESA CATEGORÍA") -> Mariscos | F10: Palta | G10: Verduras | I10: Abarrotes
A11: Ostion | B11: Mariscos | C11: =IFERROR(VLOOKUP(Productos[[#This Row],[categoria]],Categoria[],2,FALSE),"INGRESA CATEGORÍA") -> Mariscos | F11: Champiñon | G11: Verduras | I11: Postres
A12: Pulpo | B12: Mariscos | C12: =IFERROR(VLOOKUP(Productos[[#This Row],[categoria]],Categoria[],2,FALSE),"INGRESA CATEGORÍA") -> Mariscos | F12: Tortas | G12: Postres | I12: Colación
A13: Jamon Serrano | B13: Embutidos | C13: =IFERROR(VLOOKUP(Productos[[#This Row],[categoria]],Categoria[],2,FALSE),"INGRESA CATEGORÍA") -> Embutidos | F13: Colacion | G13: Colación
A14: Pepperoni | B14: Embutidos | C14: =IFERROR(VLOOKUP(Productos[[#This Row],[categoria]],Categoria[],2,FALSE),"INGRESA CATEGORÍA") -> Embutidos | F14: Chocolate | G14: Abarrotes
A15: Mozzarella Fior Di Latte | B15: Quesos | C15: =IFERROR(VLOOKUP(Productos[[#This Row],[categoria]],Categoria[],2,FALSE),"INGRESA CATEGORÍA") -> Lacteos | F15: Aceite | G15: Abarrotes
A16: ChampiÃ±on Ostra | B16: Champiñon | C16: =IFERROR(VLOOKUP(Productos[[#This Row],[categoria]],Categoria[],2,FALSE),"INGRESA CATEGORÍA") -> Verduras | F16: Postres | G16: Postres
A17: ChampiÃ±on Paris | B17: Champiñon | C17: =IFERROR(VLOOKUP(Productos[[#This Row],[categoria]],Categoria[],2,FALSE),"INGRESA CATEGORÍA") -> Verduras
A18: ChampiÃ±on Portobello | B18: Champiñon | C18: =IFERROR(VLOOKUP(Productos[[#This Row],[categoria]],Categoria[],2,FALSE),"INGRESA CATEGORÍA") -> Verduras
A19: ChampiÃ±on Shitake | B19: Champiñon | C19: =IFERROR(VLOOKUP(Productos[[#This Row],[categoria]],Categoria[],2,FALSE),"INGRESA CATEGORÍA") -> Verduras
A20: Palta Hass | B20: Palta | C20: =IFERROR(VLOOKUP(Productos[[#This Row],[categoria]],Categoria[],2,FALSE),"INGRESA CATEGORÍA") -> Verduras
A21: Tiramisu | B21: Tortas | C21: =IFERROR(VLOOKUP(Productos[[#This Row],[categoria]],Categoria[],2,FALSE),"INGRESA CATEGORÍA") -> Postres
A22: Camaron 36/40 Con Cascara | B22: Mariscos | C22: =IFERROR(VLOOKUP(Productos[[#This Row],[categoria]],Categoria[],2,FALSE),"INGRESA CATEGORÍA") -> Mariscos
A23: Camaron 36/40 Sin cascara | B23: Mariscos | C23: =IFERROR(VLOOKUP(Productos[[#This Row],[categoria]],Categoria[],2,FALSE),"INGRESA CATEGORÍA") -> Mariscos
A24: Chipiron | B24: Mariscos | C24: =IFERROR(VLOOKUP(Productos[[#This Row],[categoria]],Categoria[],2,FALSE),"INGRESA CATEGORÍA") -> Mariscos
A25: Burrata | B25: Quesos | C25: =IFERROR(VLOOKUP(Productos[[#This Row],[categoria]],Categoria[],2,FALSE),"INGRESA CATEGORÍA") -> Lacteos
A26: Parmesano | B26: Quesos | C26: =IFERROR(VLOOKUP(Productos[[#This Row],[categoria]],Categoria[],2,FALSE),"INGRESA CATEGORÍA") -> Lacteos
A27: Queso Azul | B27: Quesos | C27: =IFERROR(VLOOKUP(Productos[[#This Row],[categoria]],Categoria[],2,FALSE),"INGRESA CATEGORÍA") -> Lacteos
A28: Creme Brule | B28: Tortas | C28: =IFERROR(VLOOKUP(Productos[[#This Row],[categoria]],Categoria[],2,FALSE),"INGRESA CATEGORÍA") -> Postres
... A107: Champi��on Engiri | B107: Champiñon | C107: =IFERROR(VLOOKUP(Productos[[#This Row],[categoria]],Categoria[],2,FALSE),"INGRESA CATEGORÍA") -> Verduras

Sheet Variacion
A1: Agrupacion Personalizada | B1: Clasificacion | C1: Categoria | D1: N° de dias en periodo | E1: Fecha Inicial | F1: Fecha | G1: Nombre Artículo | H1: Existencia Previa | I1: Compras | J1: Existencia | K1: Usado | L1: Vendido | M1: Diferencia | N1: Desperdicio | O1: % Diferencia | P1: Diferencia (Costo) | Q1: % Desperdicio | R1: Desperdicio (Costo) | S1: Porcentaje de Costo | T1: Porcentaje de Costo Ideal | U1: Ingresos | V1: Existencia (Costo) | W1: Compras (Costo) | X1: Usado (Costo) | Y1: Vendido (Costo)
A2: =IFERROR(VLOOKUP(RepVariacion[[#This Row],[Nombre Artículo]],Productos[],4,FALSE),"00 Falta Info") -> 0 | B2: =IFERROR(VLOOKUP(RepVariacion[[#This Row],[Nombre Artículo]],Productos[],3,FALSE),"00 Falta Info") -> Aves | C2: =IFERROR(VLOOKUP(RepVariacion[[#This Row],[Nombre Artículo]],Productos[],2,FALSE),"00 Falta Info") -> Pollo | D2: =RepVariacion[[#This Row],[Fecha]]-RepVariacion[[#This Row],[Fecha Inicial]]+1 -> 7 | E2: 46018 | F2: 46024 | G2: Pechuga Deshuesada | H2: 21.7 | J2: 17.6 | K2: 4.1 | L2: 3.1 | M2: -1.1 | O2: -0.262 | P2: -5698.61 | S2: 0.267 | T2: 0.197 | U2: 81580.56 | V2: 92749.86 | X2: 21776.21 | Y2: 16077.59
A3: =IFERROR(VLOOKUP(RepVariacion[[#This Row],[Nombre Artículo]],Productos[],4,FALSE),"00 Falta Info") -> 0 | B3: =IFERROR(VLOOKUP(RepVariacion[[#This Row],[Nombre Artículo]],Productos[],3,FALSE),"00 Falta Info") -> Carnes | C3: =IFERROR(VLOOKUP(RepVariacion[[#This Row],[Nombre Artículo]],Productos[],2,FALSE),"00 Falta Info") -> Vacuno | D3: =RepVariacion[[#This Row],[Fecha]]-RepVariacion[[#This Row],[Fecha Inicial]]+1 -> 7 | E3: 46018 | F3: 46024 | G3: Asado de Tira | H3: 16.3 | J3: 15.6 | K3: 0.7 | M3: -0.7 | O3: -1 | P3: -11192.98 | V3: 249444 | X3: 11192.98
A4: =IFERROR(VLOOKUP(RepVariacion[[#This Row],[Nombre Artículo]],Productos[],4,FALSE),"00 Falta Info") -> 0 | B4: =IFERROR(VLOOKUP(RepVariacion[[#This Row],[Nombre Artículo]],Productos[],3,FALSE),"00 Falta Info") -> Carnes | C4: =IFERROR(VLOOKUP(RepVariacion[[#This Row],[Nombre Artículo]],Productos[],2,FALSE),"00 Falta Info") -> Vacuno | D4: =RepVariacion[[#This Row],[Fecha]]-RepVariacion[[#This Row],[Fecha Inicial]]+1 -> 7 | E4: 46018 | F4: 46024 | G4: EntraÃ±a | H4: 24.7 | J4: 16.4 | K4: 8.4 | L4: 7.6 | M4: -0.8 | O4: -0.09 | P4: -26133.9 | S4: 0.367 | T4: 0.334 | U4: 790940.99 | V4: 568377.55 | X4: 290253.09 | Y4: 264119.19
A5: =IFERROR(VLOOKUP(RepVariacion[[#This Row],[Nombre Artículo]],Productos[],4,FALSE),"00 Falta Info") -> 0 | B5: =IFERROR(VLOOKUP(RepVariacion[[#This Row],[Nombre Artículo]],Productos[],3,FALSE),"00 Falta Info") -> Carnes | C5: =IFERROR(VLOOKUP(RepVariacion[[#This Row],[Nombre Artículo]],Productos[],2,FALSE),"00 Falta Info") -> Vacuno | D5: =RepVariacion[[#This Row],[Fecha]]-RepVariacion[[#This Row],[Fecha Inicial]]+1 -> 7 | E5: 46018 | F5: 46024 | G5: Filete | H5: 36.5 | I5: 22.5 | J5: 50.9 | K5: 8.1 | L5: 5.4 | M5: -2.8 | N5: 1.3 | O5: -0.341 | P5: -38632.56 | Q5: 0.163 | R5: 18424.61 | S5: 0.301 | T5: 0.2 | U5: 374432.16 | V5: 708086.05 | W5: 314481 | X5: 112867.47 | Y5: 74713.81
A6: =IFERROR(VLOOKUP(RepVariacion[[#This Row],[Nombre Artículo]],Productos[],4,FALSE),"00 Falta Info") -> 0 | B6: =IFERROR(VLOOKUP(RepVariacion[[#This Row],[Nombre Artículo]],Productos[],3,FALSE),"00 Falta Info") -> Carnes | C6: =IFERROR(VLOOKUP(RepVariacion[[#This Row],[Nombre Artículo]],Productos[],2,FALSE),"00 Falta Info") -> Vacuno | D6: =RepVariacion[[#This Row],[Fecha]]-RepVariacion[[#This Row],[Fecha Inicial]]+1 -> 7 | E6: 46018 | F6: 46024 | G6: Filete Medallon | H6: 50.1 | J6: 38.3 | K6: 11.8 | L6: 2.8 | M6: -9 | N6: 2 | O6: -0.766 | P6: -175961.48 | Q6: 0.17 | R6: 39020.7 | S6: 1.373 | T6: 0.321 | U6: 167227 | V6: 748048.66 | X6: 229614.94 | Y6: 53653.46
A7: =IFERROR(VLOOKUP(RepVariacion[[#This Row],[Nombre Artículo]],Productos[],4,FALSE),"00 Falta Info") -> 0 | B7: =IFERROR(VLOOKUP(RepVariacion[[#This Row],[Nombre Artículo]],Productos[],3,FALSE),"00 Falta Info") -> Carnes | C7: =IFERROR(VLOOKUP(RepVariacion[[#This Row],[Nombre Artículo]],Productos[],2,FALSE),"00 Falta Info") -> Vacuno | D7: =RepVariacion[[#This Row],[Fecha]]-RepVariacion[[#This Row],[Fecha Inicial]]+1 -> 7 | E7: 46018 | F7: 46024 | G7: Mechada EntraÃ±a | H7: 20 | J7: 20.2 | K7: -0.2 | M7: 0.2 | O7: 1 | P7: 2050 | V7: 166050 | X7: -2050
A8: =IFERROR(VLOOKUP(RepVariacion[[#This Row],[Nombre Artículo]],Productos[],4,FALSE),"00 Falta Info") -> 0 | B8: =IFERROR(VLOOKUP(RepVariacion[[#This Row],[Nombre Artículo]],Productos[],3,FALSE),"00 Falta Info") -> Carnes | C8: =IFERROR(VLOOKUP(RepVariacion[[#This Row],[Nombre Artículo]],Productos[],2,FALSE),"00 Falta Info") -> Vacuno | D8: =RepVariacion[[#This Row],[Fecha]]-RepVariacion[[#This Row],[Fecha Inicial]]+1 -> 7 | E8: 46018 | F8: 46024 | G8: Plateada | H8: 14.6 | J8: 9.4 | K8: 5.2 | L8: 4.9 | M8: -0.3 | O8: -0.058 | P8: -3638.8 | S8: 0.319 | T8: 0.3 | U8: 195448.65 | V8: 112352.81 | X8: 62329.11 | Y8: 58690.31
A9: =IFERROR(VLOOKUP(RepVariacion[[#This Row],[Nombre Artículo]],Productos[],4,FALSE),"00 Falta Info") -> 0 | B9: =IFERROR(VLOOKUP(RepVariacion[[#This Row],[Nombre Artículo]],Productos[],3,FALSE),"00 Falta Info") -> Carnes | C9: =IFERROR(VLOOKUP(RepVariacion[[#This Row],[Nombre Artículo]],Productos[],2,FALSE),"00 Falta Info") -> Vacuno | D9: =RepVariacion[[#This Row],[Fecha]]-RepVariacion[[#This Row],[Fecha Inicial]]+1 -> 7 | E9: 46018 | F9: 46024 | G9: Plateada al jugo 200 gr | H9: 32.99 | I9: 24 | J9: 32.55 | K9: 24.44 | L9: 25 | M9: 0.56 | O9: 0.023 | P9: 8355 | S9: 4.809 | T9: 4.919 | U9: 76235 | V9: 488190 | W9: 360000 | X9: 366645 | Y9: 375000
A10: =IFERROR(VLOOKUP(RepVariacion[[#This Row],[Nombre Artículo]],Productos[],4,FALSE),"00 Falta Info") -> 0 | B10: =IFERROR(VLOOKUP(RepVariacion[[#This Row],[Nombre Artículo]],Productos[],3,FALSE),"00 Falta Info") -> Pescado | C10: =IFERROR(VLOOKUP(RepVariacion[[#This Row],[Nombre Artículo]],Productos[],2,FALSE),"00 Falta Info") -> Pescado | D10: =RepVariacion[[#This Row],[Fecha]]-RepVariacion[[#This Row],[Fecha Inicial]]+1 -> 7 | E10: 46018 | F10: 46024 | G10: Atun Steak | H10: 20.3 | I10: 15 | J10: 26.3 | K10: 9 | L10: 7.5 | M10: -1.5 | O10: -0.162 | P10: -13903.74 | S10: 0.237 | T10: 0.199 | U10: 362273.69 | V10: 251105.45 | W10: 143250 | X10: 85953.2 | Y10: 72049.41
A11: =IFERROR(VLOOKUP(RepVariacion[[#This Row],[Nombre Artículo]],Productos[],4,FALSE),"00 Falta Info") -> 0 | B11: =IFERROR(VLOOKUP(RepVariacion[[#This Row],[Nombre Artículo]],Productos[],3,FALSE),"00 Falta Info") -> Pescado | C11: =IFERROR(VLOOKUP(RepVariacion[[#This Row],[Nombre Artículo]],Productos[],2,FALSE),"00 Falta Info") -> Pescado | D11: =RepVariacion[[#This Row],[Fecha]]-RepVariacion[[#This Row],[Fecha Inicial]]+1 -> 7 | E11: 46018 | F11: 46024 | G11: Corvina | H11: 21.6 | I11: 55.2 | J11: 39.4 | K11: 37.5 | L11: 35.9 | M11: -1.5 | O11: -0.041 | P11: -12336.56 | S11: 0.126 | T11: 0.139 | U11: 2070491 | V11: 314933.83 | W11: 434668 | X11: 260329.17 | Y11: 287000.79
A12: =IFERROR(VLOOKUP(RepVariacion[[#This Row],[Nombre Artículo]],Productos[],4,FALSE),"00 Falta Info") -> 0 | B12: =IFERROR(VLOOKUP(RepVariacion[[#This Row],[Nombre Artículo]],Productos[],3,FALSE),"00 Falta Info") -> Pescado | C12: =IFERROR(VLOOKUP(RepVariacion[[#This Row],[Nombre Artículo]],Productos[],2,FALSE),"00 Falta Info") -> Pescado | D12: =RepVariacion[[#This Row],[Fecha]]-RepVariacion[[#This Row],[Fecha Inicial]]+1 -> 7 | E12: 46018 | F12: 46024 | G12: Salmon | H12: 33.8 | J12: 19.1 | K12: 14.8 | L12: 17.4 | M12: 2.6 | N12: 0.5 | O12: 0.176 | P12: 25937.67 | Q12: 0.031 | R12: 4521.08 | S12: 0.076 | T12: 0.09 | U12: 1928072.6 | V12: 189891.95 | X12: 147133.25 | Y12: 173070.92
A13: =IFERROR(VLOOKUP(RepVariacion[[#This Row],[Nombre Artículo]],Productos[],4,FALSE),"00 Falta Info") -> 0 | B13: =IFERROR(VLOOKUP(RepVariacion[[#This Row],[Nombre Artículo]],Productos[],3,FALSE),"00 Falta Info") -> Mariscos | C13: =IFERROR(VLOOKUP(RepVariacion[[#This Row],[Nombre Artículo]],Productos[],2,FALSE),"00 Falta Info") -> Mariscos | D13: =RepVariacion[[#This Row],[Fecha]]-RepVariacion[[#This Row],[Fecha Inicial]]+1 -> 7 | E13: 46018 | F13: 46024 | G13: Almejas | H13: 28.6 | J13: 9.9 | K13: 18.6 | L13: 2.4 | M13: -16.2 | N13: 3.3 | O13: -0.871 | P13: -49439.21 | Q13: 0.176 | R13: 9981.27 | S13: 3.512 | T13: 0.452 | U13: 16157.8 | V13: 30164.42 | X13: 56742.58 | Y13: 7303.36
A14: =IFERROR(VLOOKUP(RepVariacion[[#This Row],[Nombre Artículo]],Productos[],4,FALSE),"00 Falta Info") -> 0 | B14: =IFERROR(VLOOKUP(RepVariacion[[#This Row],[Nombre Artículo]],Productos[],3,FALSE),"00 Falta Info") -> Mariscos | C14: =IFERROR(VLOOKUP(RepVariacion[[#This Row],[Nombre Artículo]],Productos[],2,FALSE),"00 Falta Info") -> Mariscos | D14: =RepVariacion[[#This Row],[Fecha]]-RepVariacion[[#This Row],[Fecha Inicial]]+1 -> 7 | E14: 46018 | F14: 46024 | G14: Camaron 36/40 Sin cascara | H14: 18.7 | J14: 16.6 | K14: 2.1 | L14: 3 | M14: 0.9 | O14: 0.426 | P14: 6787.41 | S14: 0.124 | T14: 0.178 | U14: 128000 | V14: 125581.62 | X14: 15934.38 | Y14: 22721.8
A15: =IFERROR(VLOOKUP(RepVariacion[[#This Row],[Nombre Artículo]],Productos[],4,FALSE),"00 Falta Info") -> 0 | B15: =IFERROR(VLOOKUP(RepVariacion[[#This Row],[Nombre Artículo]],Productos[],3,FALSE),"00 Falta Info") -> Mariscos | C15: =IFERROR(VLOOKUP(RepVariacion[[#This Row],[Nombre Artículo]],Productos[],2,FALSE),"00 Falta Info") -> Mariscos | D15: =RepVariacion[[#This Row],[Fecha]]-RepVariacion[[#This Row],[Fecha Inicial]]+1 -> 7 | E15: 46018 | F15: 46024 | G15: Langostino | H15: 23.8 | J15: 24.4 | K15: -0.6 | L15: 0.7 | M15: 1.3 | O15: 2.045 | P15: 15988.83 | S15: -0.26 | T15: 0.272 | U15: 30084 | V15: 305976.49 | X15: -7819.34 | Y15: 8169.49
A16: =IFERROR(VLOOKUP(RepVariacion[[#This Row],[Nombre Artículo]],Productos[],4,FALSE),"00 Falta Info") -> 0 | B16: =IFERROR(VLOOKUP(RepVariacion[[#This Row],[Nombre Artículo]],Productos[],3,FALSE),"00 Falta Info") -> Mariscos | C16: =IFERROR(VLOOKUP(RepVariacion[[#This Row],[Nombre Artículo]],Productos[],2,FALSE),"00 Falta Info") -> Mariscos | D16: =RepVariacion[[#This Row],[Fecha]]-RepVariacion[[#This Row],[Fecha Inicial]]+1 -> 7 | E16: 46018 | F16: 46024 | G16: Locos | H16: 32.17 | I16: 6 | J16: 35.19 | K16: 2.98 | L16: 3.35 | M16: 0.37 | N16: 0.09 | O16: 0.125 | P16: 8712.45 | Q16: 0.03 | R16: 2117.59 | S16: 0.35 | T16: 0.394 | U16: 199803.48 | V16: 825416.5 | W16: 141000 | X16: 69947.83 | Y16: 78684.25
A17: =IFERROR(VLOOKUP(RepVariacion[[#This Row],[Nombre Artículo]],Productos[],4,FALSE),"00 Falta Info") -> 0 | B17: =IFERROR(VLOOKUP(RepVariacion[[#This Row],[Nombre Artículo]],Productos[],3,FALSE),"00 Falta Info") -> Mariscos | C17: =IFERROR(VLOOKUP(RepVariacion[[#This Row],[Nombre Artículo]],Productos[],2,FALSE),"00 Falta Info") -> Mariscos | D17: =RepVariacion[[#This Row],[Fecha]]-RepVariacion[[#This Row],[Fecha Inicial]]+1 -> 7 | E17: 46018 | F17: 46024 | G17: Ostion | H17: 21.5 | J17: 21.7 | K17: -0.2 | L17: 0.3 | M17: 0.5 | N17: 0.1 | O17: 2.373 | P17: 7403.22 | Q17: -0.425 | R17: 1325.87 | S17: -0.352 | T17: 0.483 | U17: 8868.07 | V17: 331419.4 | X17: -3119.47 | Y17: 4283.76
A18: =IFERROR(VLOOKUP(RepVariacion[[#This Row],[Nombre Artículo]],Productos[],4,FALSE),"00 Falta Info") -> 0 | B18: =IFERROR(VLOOKUP(RepVariacion[[#This Row],[Nombre Artículo]],Productos[],3,FALSE),"00 Falta Info") -> Mariscos | C18: =IFERROR(VLOOKUP(RepVariacion[[#This Row],[Nombre Artículo]],Productos[],2,FALSE),"00 Falta Info") -> Mariscos | D18: =RepVariacion[[#This Row],[Fecha]]-RepVariacion[[#This Row],[Fecha Inicial]]+1 -> 7 | E18: 46018 | F18: 46024 | G18: Ostion sin concha | H18: 3 | J18: 3 | V18: 44700
A19: =IFERROR(VLOOKUP(RepVariacion[[#This Row],[Nombre Artículo]],Productos[],4,FALSE),"00 Falta Info") -> 0 | B19: =IFERROR(VLOOKUP(RepVariacion[[#This Row],[Nombre Artículo]],Productos[],3,FALSE),"00 Falta Info") -> Mariscos | C19: =IFERROR(VLOOKUP(RepVariacion[[#This Row],[Nombre Artículo]],Productos[],2,FALSE),"00 Falta Info") -> Mariscos | D19: =RepVariacion[[#This Row],[Fecha]]-RepVariacion[[#This Row],[Fecha Inicial]]+1 -> 7 | E19: 46018 | F19: 46024 | G19: Ostras | H19: 1.3 | I19: 13.2 | J19: 5.8 | K19: 8.6 | L19: 10.3 | M19: 1.7 | O19: 0.193 | P19: 24157.8 | S19: 0.081 | T19: 0.101 | U19: 1479181.7 | V19: 84393.43 | W19: 185950 | X19: 119955.03 | Y19: 149507.44
A20: =IFERROR(VLOOKUP(RepVariacion[[#This Row],[Nombre Artículo]],Productos[],4,FALSE),"00 Falta Info") -> 0 | B20: =IFERROR(VLOOKUP(RepVariacion[[#This Row],[Nombre Artículo]],Productos[],3,FALSE),"00 Falta Info") -> Mariscos | C20: =IFERROR(VLOOKUP(RepVariacion[[#This Row],[Nombre Artículo]],Productos[],2,FALSE),"00 Falta Info") -> Mariscos | D20: =RepVariacion[[#This Row],[Fecha]]-RepVariacion[[#This Row],[Fecha Inicial]]+1 -> 7 | E20: 46018 | F20: 46024 | G20: Pulpo | H20: 12.8 | J20: 5.8 | K20: 6.9 | L20: 4.6 | M20: -2.4 | N20: 1.3 | O20: -0.343 | P20: -21997.66 | Q20: 0.192 | R20: 12291.26 | S20: 0.502 | T20: 0.33 | U20: 127850.95 | V20: 53915.86 | X20: 64139.31 | Y20: 42141.65
A21: =IFERROR(VLOOKUP(RepVariacion[[#This Row],[Nombre Artículo]],Productos[],4,FALSE),"00 Falta Info") -> 0 | B21: =IFERROR(VLOOKUP(RepVariacion[[#This Row],[Nombre Artículo]],Productos[],3,FALSE),"00 Falta Info") -> Embutidos | C21: =IFERROR(VLOOKUP(RepVariacion[[#This Row],[Nombre Artículo]],Productos[],2,FALSE),"00 Falta Info") -> Embutidos | D21: =RepVariacion[[#This Row],[Fecha]]-RepVariacion[[#This Row],[Fecha Inicial]]+1 -> 7 | E21: 46018 | F21: 46024 | G21: Jamon Serrano | H21: 8.4 | J21: 6.6 | K21: 1.9 | L21: 2.1 | M21: 0.2 | O21: 0.124 | P21: 5388.81 | S21: 0.38 | T21: 0.428 | U21: 114215.77 | V21: 150564.96 | X21: 43443.69 | Y21: 48832.5
A22: =IFERROR(VLOOKUP(RepVariacion[[#This Row],[Nombre Artículo]],Productos[],4,FALSE),"00 Falta Info") -> 0 | B22: =IFERROR(VLOOKUP(RepVariacion[[#This Row],[Nombre Artículo]],Productos[],3,FALSE),"00 Falta Info") -> Embutidos | C22: =IFERROR(VLOOKUP(RepVariacion[[#This Row],[Nombre Artículo]],Productos[],2,FALSE),"00 Falta Info") -> Embutidos | D22: =RepVariacion[[#This Row],[Fecha]]-RepVariacion[[#This Row],[Fecha Inicial]]+1 -> 7 | E22: 46018 | F22: 46024 | G22: Pepperoni | H22: 6.7 | J22: 5.8 | K22: 1 | L22: 1 | M22: 0.1 | O22: 0.06 | P22: 612.85 | S22: 0.126 | T22: 0.134 | U22: 80732.49 | V22: 59872.29 | X22: 10189.92 | Y22: 10802.77
A23: =IFERROR(VLOOKUP(RepVariacion[[#This Row],[Nombre Artículo]],Productos[],4,FALSE),"00 Falta Info") -> 0 | B23: =IFERROR(VLOOKUP(RepVariacion[[#This Row],[Nombre Artículo]],Productos[],3,FALSE),"00 Falta Info") -> Lacteos | C23: =IFERROR(VLOOKUP(RepVariacion[[#This Row],[Nombre Artículo]],Productos[],2,FALSE),"00 Falta Info") -> Quesos | D23: =RepVariacion[[#This Row],[Fecha]]-RepVariacion[[#This Row],[Fecha Inicial]]+1 -> 7 | E23: 46018 | F23: 46024 | G23: Burrata | H23: 143 | I23: 32 | J23: 152 | K23: 23 | L23: 24 | M23: 1 | O23: 0.043 | P23: 4191.3 | S23: 0.526 | T23: 0.548 | U23: 183436.73 | V23: 637078.02 | W23: 134080 | X23: 96408.39 | Y23: 100591.27
A24: =IFERROR(VLOOKUP(RepVariacion[[#This Row],[Nombre Artículo]],Productos[],4,FALSE),"00 Falta Info") -> 0 | B24: =IFERROR(VLOOKUP(RepVariacion[[#This Row],[Nombre Artículo]],Productos[],3,FALSE),"00 Falta Info") -> Lacteos | C24: =IFERROR(VLOOKUP(RepVariacion[[#This Row],[Nombre Artículo]],Productos[],2,FALSE),"00 Falta Info") -> Quesos | D24: =RepVariacion[[#This Row],[Fecha]]-RepVariacion[[#This Row],[Fecha Inicial]]+1 -> 7 | E24: 46018 | F24: 46024 | G24: Mascarpone | H24: 9 | J24: 8.9 | K24: 0.1 | L24: 3.4 | M24: 3.2 | O24: 32.5
A25: =IFERROR(VLOOKUP(RepVariacion[[#This Row],[Nombre Artículo]],Productos[],4,FALSE),"00 Falta Info") -> 0 | B25: =IFERROR(VLOOKUP(RepVariacion[[#This Row],[Nombre Artículo]],Productos[],3,FALSE),"00 Falta Info") -> Lacteos | C25: =IFERROR(VLOOKUP(RepVariacion[[#This Row],[Nombre Artículo]],Productos[],2,FALSE),"00 Falta Info") -> Quesos | D25: =RepVariacion[[#This Row],[Fecha]]-RepVariacion[[#This Row],[Fecha Inicial]]+1 -> 7 | E25: 46018 | F25: 46024 | G25: Mozzarella Fior Di Latte | H25: 44.8 | I25: 14 | J25: 46.3 | K25: 12.5 | L25: 13 | M25: 0.5 | O25: 0.04 | P25: 6107.98 | S25: 0.169 | T25: 0.177 | U25: 893747.01 | V25: 564735.1 | W25: 173460 | X25: 151388.99 | Y25: 158529.68
A26: =IFERROR(VLOOKUP(RepVariacion[[#This Row],[Nombre Artículo]],Productos[],4,FALSE),"00 Falta Info") -> 0 | B26: =IFERROR(VLOOKUP(RepVariacion[[#This Row],[Nombre Artículo]],Productos[],3,FALSE),"00 Falta Info") -> Lacteos | C26: =IFERROR(VLOOKUP(RepVariacion[[#This Row],[Nombre Artículo]],Productos[],2,FALSE),"00 Falta Info") -> Quesos | D26: =RepVariacion[[#This Row],[Fecha]]-RepVariacion[[#This Row],[Fecha Inicial]]+1 -> 7 | E26: 46018 | F26: 46024 | G26: Parmesano | H26: 11.7 | J26: 10.7 | K26: 1 | L26: 1 | O26: -0.02 | P26: -272.79 | S26: 0.053 | T26: 0.052 | U26: 253622.56 | V26: 138941.04 | X26: 13522.59 | Y26: 13249.8
A27: =IFERROR(VLOOKUP(RepVariacion[[#This Row],[Nombre Artículo]],Productos[],4,FALSE),"00 Falta Info") -> 0 | B27: =IFERROR(VLOOKUP(RepVariacion[[#This Row],[Nombre Artículo]],Productos[],3,FALSE),"00 Falta Info") -> Lacteos | C27: =IFERROR(VLOOKUP(RepVariacion[[#This Row],[Nombre Artículo]],Productos[],2,FALSE),"00 Falta Info") -> Quesos | D27: =RepVariacion[[#This Row],[Fecha]]-RepVariacion[[#This Row],[Fecha Inicial]]+1 -> 7 | E27: 46018 | F27: 46024 | G27: Provoleta | H27: 7.6 | I27: 10.5 | J27: 16 | K27: 2.1 | L27: 1.7 | M27: -0.4 | O27: -0.174 | P27: -5002.06 | S27: 0.219 | T27: 0.184 | U27: 129412 | V27: 222357.65 | W27: 146895 | X27: 28399.75 | Y27: 23805.81
A28: =IFERROR(VLOOKUP(RepVariacion[[#This Row],[Nombre Artículo]],Productos[],4,FALSE),"00 Falta Info") -> 0 | B28: =IFERROR(VLOOKUP(RepVariacion[[#This Row],[Nombre Artículo]],Productos[],3,FALSE),"00 Falta Info") -> Lacteos | C28: =IFERROR(VLOOKUP(RepVariacion[[#This Row],[Nombre Artículo]],Productos[],2,FALSE),"00 Falta Info") -> Quesos | D28: =RepVariacion[[#This Row],[Fecha]]-RepVariacion[[#This Row],[Fecha Inicial]]+1 -> 7 | E28: 46018 | F28: 46024 | G28: Queso Azul | H28: 1.1 | I28: 5 | J28: 5.6 | K28: 0.5 | L28: 0.4 | M28: -0.1 | O28: -0.255 | P28: -1720.77 | S28: 0.231 | T28: 0.172 | U28: 29213.36 | V28: 78497.71 | W28: 69950 | X28: 6757.03 | Y28: 5036.39
A29: =IFERROR(VLOOKUP(RepVariacion[[#This Row],[Nombre Artículo]],Productos[],4,FALSE),"00 Falta Info") -> 0 | B29: =IFERROR(VLOOKUP(RepVariacion[[#This Row],[Nombre Artículo]],Productos[],3,FALSE),"00 Falta Info") -> Lacteos | C29: =IFERROR(VLOOKUP(RepVariacion[[#This Row],[Nombre Artículo]],Productos[],2,FALSE),"00 Falta Info") -> Quesos | D29: =RepVariacion[[#This Row],[Fecha]]-RepVariacion[[#This Row],[Fecha Inicial]]+1 -> 7 | E29: 46018 | F29: 46024 | G29: Queso Brie | H29: 4.4 | J29: 3.6 | K29: 0.8 | L29: 0.5 | M29: -0.3 | O29: -0.372 | P29: -7505.48 | S29: 0.246 | T29: 0.155 | U29: 82044 | V29: 92550.65 | X29: 20183.65 | Y29: 12678.17
A30: =IFERROR(VLOOKUP(RepVariacion[[#This Row],[Nombre Artículo]],Productos[],4,FALSE),"00 Falta Info") -> 0 | B30: =IFERROR(VLOOKUP(RepVariacion[[#This Row],[Nombre Artículo]],Productos[],3,FALSE),"00 Falta Info") -> Lacteos | C30: =IFERROR(VLOOKUP(RepVariacion[[#This Row],[Nombre Artículo]],Productos[],2,FALSE),"00 Falta Info") -> Quesos | D30: =RepVariacion[[#This Row],[Fecha]]-RepVariacion[[#This Row],[Fecha Inicial]]+1 -> 7 | E30: 46018 | F30: 46024 | G30: Queso Crema | H30: 8.8 | J30: 8.6 | K30: 0.2 | L30: 0.7 | M30: 0.5 | N30: 0.1 | O30: 1.99 | P30: 4644.54 | Q30: 0.639 | R30: 1492.7 | S30: 0.125 | T30: 0.374 | U30: 18656.35 | V30: 87825.26 | X30: 2334.29 | Y30: 6978.83
A31: =IFERROR(VLOOKUP(RepVariacion[[#This Row],[Nombre Artículo]],Productos[],4,FALSE),"00 Falta Info") -> 0 | B31: =IFERROR(VLOOKUP(RepVariacion[[#This Row],[Nombre Artículo]],Productos[],3,FALSE),"00 Falta Info") -> Lacteos | C31: =IFERROR(VLOOKUP(RepVariacion[[#This Row],[Nombre Artículo]],Productos[],2,FALSE),"00 Falta Info") -> Quesos | D31: =RepVariacion[[#This Row],[Fecha]]-RepVariacion[[#This Row],[Fecha Inicial]]+1 -> 7 | E31: 46018 | F31: 46024 | G31: Queso de Cabra | H31: 1.8 | I31: 5.9 | J31: 7.3 | K31: 0.4 | L31: 0.7 | M31: 0.3 | O31: 0.746 | P31: 5427.24 | S31: 0.067 | T31: 0.116 | U31: 109268.44 | V31: 132722.34 | W31: 107630 | X31: 7280.95 | Y31: 12705.91
A32: =IFERROR(VLOOKUP(RepVariacion[[#This Row],[Nombre Artículo]],Productos[],4,FALSE),"00 Falta Info") -> 0 | B32: =IFERROR(VLOOKUP(RepVariacion[[#This Row],[Nombre Artículo]],Productos[],3,FALSE),"00 Falta Info") -> Abarrotes | C32: =IFERROR(VLOOKUP(RepVariacion[[#This Row],[Nombre Artículo]],Productos[],2,FALSE),"00 Falta Info") -> Chocolate | D32: =RepVariacion[[#This Row],[Fecha]]-RepVariacion[[#This Row],[Fecha Inicial]]+1 -> 7 | E32: 46018 | F32: 46024 | G32: Belcolade Bitter | H32: 19.3 | J32: 20.6 | K32: -1.3 | L32: 0.1 | M32: 1.4 | O32: 1.08
A33: =IFERROR(VLOOKUP(RepVariacion[[#This Row],[Nombre Artículo]],Productos[],4,FALSE),"00 Falta Info") -> 0 | B33: =IFERROR(VLOOKUP(RepVariacion[[#This Row],[Nombre Artículo]],Productos[],3,FALSE),"00 Falta Info") -> Abarrotes | C33: =IFERROR(VLOOKUP(RepVariacion[[#This Row],[Nombre Artículo]],Productos[],2,FALSE),"00 Falta Info") -> Chocolate | D33: =RepVariacion[[#This Row],[Fecha]]-RepVariacion[[#This Row],[Fecha Inicial]]+1 -> 7 | E33: 46018 | F33: 46024 | G33: Belcolade Blanco | H33: 8.5 | J33: 8.3 | K33: 0.3 | M33: -0.3 | O33: -1 | P33: -2765.83 | Q33: 0.126 | R33: 348.54 | V33: 81653.38 | X33: 2765.83
A34: =IFERROR(VLOOKUP(RepVariacion[[#This Row],[Nombre Artículo]],Productos[],4,FALSE),"00 Falta Info") -> 0 | B34: =IFERROR(VLOOKUP(RepVariacion[[#This Row],[Nombre Artículo]],Productos[],3,FALSE),"00 Falta Info") -> Abarrotes | C34: =IFERROR(VLOOKUP(RepVariacion[[#This Row],[Nombre Artículo]],Productos[],2,FALSE),"00 Falta Info") -> Chocolate | D34: =RepVariacion[[#This Row],[Fecha]]-RepVariacion[[#This Row],[Fecha Inicial]]+1 -> 7 | E34: 46018 | F34: 46024 | G34: Belcolade De Leche | H34: 10.3 | J34: 9.7 | K34: 0.6 | M34: -0.6 | O34: -1 | Q34: 0.015
A35: =IFERROR(VLOOKUP(RepVariacion[[#This Row],[Nombre Artículo]],Productos[],4,FALSE),"00 Falta Info") -> 0 | B35: =IFERROR(VLOOKUP(RepVariacion[[#This Row],[Nombre Artículo]],Productos[],3,FALSE),"00 Falta Info") -> Abarrotes | C35: =IFERROR(VLOOKUP(RepVariacion[[#This Row],[Nombre Artículo]],Productos[],2,FALSE),"00 Falta Info") -> Aceite | D35: =RepVariacion[[#This Row],[Fecha]]-RepVariacion[[#This Row],[Fecha Inicial]]+1 -> 7 | E35: 46018 | F35: 46024 | G35: Aceite Vegetal 900ml | H35: 26 | I35: 12 | J35: 19 | K35: 19 | M35: -19 | O35: -1 | P35: -30335.65 | V35: 30335.65 | W35: 19164 | X35: 30323.01
A36: =IFERROR(VLOOKUP(RepVariacion[[#This Row],[Nombre Artículo]],Productos[],4,FALSE),"00 Falta Info") -> 0 | B36: =IFERROR(VLOOKUP(RepVariacion[[#This Row],[Nombre Artículo]],Productos[],3,FALSE),"00 Falta Info") -> Verduras | C36: =IFERROR(VLOOKUP(RepVariacion[[#This Row],[Nombre Artículo]],Productos[],2,FALSE),"00 Falta Info") -> Champiñon | D36: =RepVariacion[[#This Row],[Fecha]]-RepVariacion[[#This Row],[Fecha Inicial]]+1 -> 7 | E36: 46018 | F36: 46024 | G36: ChampiÃ±on Ostra | H36: 2.7 | I36: 1.6 | J36: 0.8 | K36: 3.5 | L36: 3.3 | M36: -0.2 | O36: -0.066 | P36: -3849.35 | S36: 0.1 | T36: 0.084 | U36: 646221.38 | V36: 13109.5 | W36: 26720 | X36: 64445 | Y36: 54442
A37: =IFERROR(VLOOKUP(RepVariacion[[#This Row],[Nombre Artículo]],Productos[],4,FALSE),"00 Falta Info") -> 0 | B37: =IFERROR(VLOOKUP(RepVariacion[[#This Row],[Nombre Artículo]],Productos[],3,FALSE),"00 Falta Info") -> Verduras | C37: =IFERROR(VLOOKUP(RepVariacion[[#This Row],[Nombre Artículo]],Productos[],2,FALSE),"00 Falta Info") -> Champiñon | D37: =RepVariacion[[#This Row],[Fecha]]-RepVariacion[[#This Row],[Fecha Inicial]]+1 -> 7 | E37: 46018 | F37: 46024 | G37: ChampiÃ±on Portobello | H37: 1 | I37: 5 | J37: 3.1 | K37: 3 | L37: 3.1 | M37: 0.1 | O37: 0.045 | P37: 1722.5 | S37: 0.079 | T37: 0.082 | U37: 490177.42 | V37: 39936 | W37: 65000 | X37: 38577.5 | Y37: 40300
A38: =IFERROR(VLOOKUP(RepVariacion[[#This Row],[Nombre Artículo]],Productos[],4,FALSE),"00 Falta Info") -> 0 | B38: =IFERROR(VLOOKUP(RepVariacion[[#This Row],[Nombre Artículo]],Productos[],3,FALSE),"00 Falta Info") -> Verduras | C38: =IFERROR(VLOOKUP(RepVariacion[[#This Row],[Nombre Artículo]],Productos[],2,FALSE),"00 Falta Info") -> Palta | D38: =RepVariacion[[#This Row],[Fecha]]-RepVariacion[[#This Row],[Fecha Inicial]]+1 -> 7 | E38: 46018 | F38: 46024 | G38: Palta Hass | H38: 12.5 | I38: 15 | J38: 11 | K38: 16.5 | L38: 13.2 | M38: -3.3 | N38: 3.2 | O38: -0.199 | P38: -14738.61 | Q38: 0.192 | R38: 14274.59 | S38: 0.241 | T38: 0.193 | U38: 307575.28 | V38: 49451.09 | W38: 67500 | X38: 74197.63 | Y38: 59459.01
A39: =IFERROR(VLOOKUP(RepVariacion[[#This Row],[Nombre Artículo]],Productos[],4,FALSE),"00 Falta Info") -> 0 | B39: =IFERROR(VLOOKUP(RepVariacion[[#This Row],[Nombre Artículo]],Productos[],3,FALSE),"00 Falta Info") -> Postres | C39: =IFERROR(VLOOKUP(RepVariacion[[#This Row],[Nombre Artículo]],Productos[],2,FALSE),"00 Falta Info") -> Tortas | D39: =RepVariacion[[#This Row],[Fecha]]-RepVariacion[[#This Row],[Fecha Inicial]]+1 -> 7 | E39: 46018 | F39: 46024 | G39: Cheesecake clasico | H39: 18 | I39: 16 | J39: 27 | K39: 7 | L39: 6 | M39: -1 | N39: 1 | O39: -0.143 | P39: -1100 | Q39: 0.143 | R39: 1100 | S39: 0.576 | T39: 0.494 | U39: 13367.45 | V39: 29700 | W39: 17600 | X39: 7700 | Y39: 6600
A40: =IFERROR(VLOOKUP(RepVariacion[[#This Row],[Nombre Artículo]],Productos[],4,FALSE),"00 Falta Info") -> 0 | B40: =IFERROR(VLOOKUP(RepVariacion[[#This Row],[Nombre Artículo]],Productos[],3,FALSE),"00 Falta Info") -> Postres | C40: =IFERROR(VLOOKUP(RepVariacion[[#This Row],[Nombre Artículo]],Productos[],2,FALSE),"00 Falta Info") -> Tortas | D40: =RepVariacion[[#This Row],[Fecha]]-RepVariacion[[#This Row],[Fecha Inicial]]+1 -> 7 | E40: 46018 | F40: 46024 | G40: Galleta new york | H40: 59 | J40: 55 | K40: 4 | L40: 3 | M40: -1 | N40: 1 | O40: -0.25 | P40: -847 | Q40: 0.25 | R40: 847 | S40: 0.328 | T40: 0.246 | U40: 10336 | V40: 46585 | X40: 3388 | Y40: 2541
...

Sheet Intelipar
A1: Agrupacion Personalizada | B1: Clasificacion | C1: Categoria | D1: Fecha de cierre | E1: Nombre de Articulo | F1: Usado | G1: Existencia (Costo) | H1: Existencia | I1: Tamaño de Articulo | J1: Costo Unitario | K1: Consumo Historico | L1: Orden UDM | M1: Proveedor | N1: Compras Realizadas | O1: Inicio del periodo | P1: Fecha de cierre del periodo | Q1: Dias de sugerencia | R1: Dias de despacho | S1: % de cob | T1: Fecha de envio de sugerencia | U1: Rango de periodo | V1: Par2 | W1: Compra sugerida | X1: $ Compra sugerida | Y1: Dias Restantes | Z1: Exceso de Inventario
A2: =IFERROR(VLOOKUP(InteliPar[[#This Row],[Nombre de Articulo]],Productos[],4,FALSE),"00 Falta Info") -> 0 | B2: =IFERROR(VLOOKUP(InteliPar[[#This Row],[Nombre de Articulo]],Productos[],3,FALSE),"00 Falta Info") -> Aves | C2: =IFERROR(VLOOKUP(InteliPar[[#This Row],[Nombre de Articulo]],Productos[],2,FALSE),"00 Falta Info") -> Pollo | D2: 46024 | E2: Pechuga Deshuesada | F2: 5.6 | G2: 114526 | H2: 21.73 | I2: 1 kg | J2: 5269.88 | K2: 6.3 | L2: KG | M2: Sociedad bravo y hermanos limitada | N2: 15 | O2: 46010 | P2: 46017 | Q2: 7 | R2: 3 | S2: 0.25 | T2: 46018 | U2: 8 | V2: 10 | W2: 0 | X2: 0 | Y2: 28 | Z2: 43575.32
A3: =IFERROR(VLOOKUP(InteliPar[[#This Row],[Nombre de Articulo]],Productos[],4,FALSE),"00 Falta Info") -> 0 | B3: =IFERROR(VLOOKUP(InteliPar[[#This Row],[Nombre de Articulo]],Productos[],3,FALSE),"00 Falta Info") -> Carnes | C3: =IFERROR(VLOOKUP(InteliPar[[#This Row],[Nombre de Articulo]],Productos[],2,FALSE),"00 Falta Info") -> Vacuno | D3: 46024 | E3: Asado de Tira | F3: -0.3 | G3: 263835 | H3: 16.5 | I3: 1 kg | J3: 15990 | K3: 0.2 | L3: KG | M3: Frigorifico de Osorno S.A. | N3: 0 | O3: 46010 | P3: 46017 | Q3: 7 | R3: 3 | S3: 0.25 | T3: 46018 | U3: 8 | V3: 1 | W3: 0 | X3: 0 | Y3: 660 | Z3: 256839.38
A4: =IFERROR(VLOOKUP(InteliPar[[#This Row],[Nombre de Articulo]],Productos[],4,FALSE),"00 Falta Info") -> 0 | B4: =IFERROR(VLOOKUP(InteliPar[[#This Row],[Nombre de Articulo]],Productos[],3,FALSE),"00 Falta Info") -> Carnes | C4: =IFERROR(VLOOKUP(InteliPar[[#This Row],[Nombre de Articulo]],Productos[],2,FALSE),"00 Falta Info") -> Vacuno | D4: 46024 | E4: EntraÃ±a | F4: 183.3 | G4: 858631 | H4: 123.54 | I4: 200 g | J4: 6950.51 | K4: 207.1 | L4: UNI | M4: Frigorifico de Osorno S.A. | N4: 200 | O4: 46010 | P4: 46017 | Q4: 7 | R4: 3 | S4: 0.25 | T4: 46018 | U4: 8 | V4: 324 | W4: 201 | X4: 1397052.5 | Y4: 5 | Z4: 0
A5: =IFERROR(VLOOKUP(InteliPar[[#This Row],[Nombre de Articulo]],Productos[],4,FALSE),"00 Falta Info") -> 0 | B5: =IFERROR(VLOOKUP(InteliPar[[#This Row],[Nombre de Articulo]],Productos[],3,FALSE),"00 Falta Info") -> Carnes | C5: =IFERROR(VLOOKUP(InteliPar[[#This Row],[Nombre de Articulo]],Productos[],2,FALSE),"00 Falta Info") -> Vacuno | D5: 46024 | E5: Filete | F5: 26.1 | G5: 506472 | H5: 36.55 | I5: 1 kg | J5: 13857.17 | K5: 37.3 | L5: KG | M5: Frigorifico de Osorno S.A. | N5: 0 | O5: 46010 | P5: 46017 | Q5: 7 | R5: 3 | S5: 0.25 | T5: 46018 | U5: 8 | V5: 59 | W5: 23 | X5: 318714.91 | Y5: 8 | Z5: 0
A6: =IFERROR(VLOOKUP(InteliPar[[#This Row],[Nombre de Articulo]],Productos[],4,FALSE),"00 Falta Info") -> 0 | B6: =IFERROR(VLOOKUP(InteliPar[[#This Row],[Nombre de Articulo]],Productos[],3,FALSE),"00 Falta Info") -> Carnes | C6: =IFERROR(VLOOKUP(InteliPar[[#This Row],[Nombre de Articulo]],Productos[],2,FALSE),"00 Falta Info") -> Vacuno | D6: 46024 | E6: Filete Baston | I6: 1 kg | K6: 6.4 | L6: KG | M6: Natural Food Services SPA | N6: 0 | O6: 46010 | P6: 46017 | Q6: 7 | R6: 3 | S6: 0.25 | T6: 46018 | U6: 8 | V6: 10 | W6: 10 | X6: 0 | Y6: 0 | Z6: 0
A7: =IFERROR(VLOOKUP(InteliPar[[#This Row],[Nombre de Articulo]],Productos[],4,FALSE),"00 Falta Info") -> 0 | B7: =IFERROR(VLOOKUP(InteliPar[[#This Row],[Nombre de Articulo]],Productos[],3,FALSE),"00 Falta Info") -> Carnes | C7: =IFERROR(VLOOKUP(InteliPar[[#This Row],[Nombre de Articulo]],Productos[],2,FALSE),"00 Falta Info") -> Vacuno | D7: 46024 | E7: Filete Medallon | F7: 54.8 | G7: 977664 | H7: 250.55 | I7: 200 g | J7: 3902.07 | K7: 60.1 | L7: UNI | M7: Alimentos San Martin SPA | N7: 125 | O7: 46010 | P7: 46017 | Q7: 7 | R7: 3 | S7: 0.25 | T7: 46018 | U7: 8 | V7: 94 | W7: 0 | X7: 0 | Y7: 33 | Z7: 454371.66
A8: =IFERROR(VLOOKUP(InteliPar[[#This Row],[Nombre de Articulo]],Productos[],4,FALSE),"00 Falta Info") -> 0 | B8: =IFERROR(VLOOKUP(InteliPar[[#This Row],[Nombre de Articulo]],Productos[],3,FALSE),"00 Falta Info") -> Carnes | C8: =IFERROR(VLOOKUP(InteliPar[[#This Row],[Nombre de Articulo]],Productos[],2,FALSE),"00 Falta Info") -> Vacuno | D8: 46024 | E8: Mechada EntraÃ±a | G8: 164000 | H8: 20 | I8: 1 kg | J8: 8200 | K8: 0 | L8: KG | M8: Natural Food Services SPA | N8: 0 | O8: 46010 | P8: 46017 | Q8: 7 | R8: 3 | S8: 0.25 | T8: 46018 | U8: 8 | V8: 0 | W8: 0 | X8: 0 | Y8: 0 | Z8: 0
A9: =IFERROR(VLOOKUP(InteliPar[[#This Row],[Nombre de Articulo]],Productos[],4,FALSE),"00 Falta Info") -> 0 | B9: =IFERROR(VLOOKUP(InteliPar[[#This Row],[Nombre de Articulo]],Productos[],3,FALSE),"00 Falta Info") -> Carnes | C9: =IFERROR(VLOOKUP(InteliPar[[#This Row],[Nombre de Articulo]],Productos[],2,FALSE),"00 Falta Info") -> Vacuno | D9: 46024 | E9: Plateada | F9: 9.5 | G9: 174682 | H9: 14.64 | I9: 1 kg | J9: 11933.7 | K9: 58.8 | L9: KG | M9: Frigorifico de Osorno S.A. | N9: 0 | O9: 46010 | P9: 46017 | Q9: 7 | R9: 3 | S9: 0.25 | T9: 46018 | U9: 8 | V9: 92 | W9: 78 | X9: 930828.6 | Y9: 2 | Z9: 0
A10: =IFERROR(VLOOKUP(InteliPar[[#This Row],[Nombre de Articulo]],Productos[],4,FALSE),"00 Falta Info") -> 0 | B10: =IFERROR(VLOOKUP(InteliPar[[#This Row],[Nombre de Articulo]],Productos[],3,FALSE),"00 Falta Info") -> Carnes | C10: =IFERROR(VLOOKUP(InteliPar[[#This Row],[Nombre de Articulo]],Productos[],2,FALSE),"00 Falta Info") -> Vacuno | D10: 46024 | E10: Plateada al jugo 200 gr | F10: 75.7 | G10: 494835 | H10: 164.94 | I10: 200 g | J10: 3000 | K10: -1.9 | L10: EACH | M10: Natural Food Services SPA | N10: 80 | O10: 46010 | P10: 46017 | Q10: 7 | R10: 3 | S10: 0.25 | T10: 46018 | U10: 8 | V10: -3 | W10: 0 | X10: 0 | Y10: -694 | Z10: 0
A11: =IFERROR(VLOOKUP(InteliPar[[#This Row],[Nombre de Articulo]],Productos[],4,FALSE),"00 Falta Info") -> 0 | B11: =IFERROR(VLOOKUP(InteliPar[[#This Row],[Nombre de Articulo]],Productos[],3,FALSE),"00 Falta Info") -> Pescado | C11: =IFERROR(VLOOKUP(InteliPar[[#This Row],[Nombre de Articulo]],Productos[],2,FALSE),"00 Falta Info") -> Pescado | D11: 46024 | E11: Atun Steak | F11: 30 | G11: 193809 | H11: 20.29 | I11: 1 kg | J11: 9549.99 | K11: 30 | L11: KG | M11: South Wind | N11: 15 | O11: 46010 | P11: 46017 | Q11: 7 | R11: 3 | S11: 0.25 | T11: 46018 | U11: 8 | V11: 47 | W11: 27 | X11: 257849.73 | Y11: 5 | Z11: 0
A12: =IFERROR(VLOOKUP(InteliPar[[#This Row],[Nombre de Articulo]],Productos[],4,FALSE),"00 Falta Info") -> 0 | B12: =IFERROR(VLOOKUP(InteliPar[[#This Row],[Nombre de Articulo]],Productos[],3,FALSE),"00 Falta Info") -> Pescado | C12: =IFERROR(VLOOKUP(InteliPar[[#This Row],[Nombre de Articulo]],Productos[],2,FALSE),"00 Falta Info") -> Pescado | D12: 46024 | E12: Corvina | F12: 33.4 | G12: 140595 | H12: 21.63 | I12: 1 kg | J12: 6500 | K12: 33.4 | L12: KG | M12: Delicias del Mar de Matias SPA | N12: 49.4 | O12: 46010 | P12: 46017 | Q12: 7 | R12: 3 | S12: 0.25 | T12: 46018 | U12: 8 | V12: 53 | W12: 32 | X12: 208000 | Y12: 5 | Z12: 0
A13: =IFERROR(VLOOKUP(InteliPar[[#This Row],[Nombre de Articulo]],Productos[],4,FALSE),"00 Falta Info") -> 0 | B13: =IFERROR(VLOOKUP(InteliPar[[#This Row],[Nombre de Articulo]],Productos[],3,FALSE),"00 Falta Info") -> Pescado | C13: =IFERROR(VLOOKUP(InteliPar[[#This Row],[Nombre de Articulo]],Productos[],2,FALSE),"00 Falta Info") -> Pescado | D13: 46024 | E13: Palometa | I13: 1 kg | K13: 55.4 | L13: KG | M13: Delicias del Mar de Matias SPA | N13: 0 | O13: 46010 | P13: 46017 | Q13: 7 | R13: 3 | S13: 0.25 | T13: 46018 | U13: 8 | V13: 87 | W13: 87 | X13: 0 | Y13: 0 | Z13: 0
A14: =IFERROR(VLOOKUP(InteliPar[[#This Row],[Nombre de Articulo]],Productos[],4,FALSE),"00 Falta Info") -> 0 | B14: =IFERROR(VLOOKUP(InteliPar[[#This Row],[Nombre de Articulo]],Productos[],3,FALSE),"00 Falta Info") -> Pescado | C14: =IFERROR(VLOOKUP(InteliPar[[#This Row],[Nombre de Articulo]],Productos[],2,FALSE),"00 Falta Info") -> Pescado | D14: 46024 | E14: Salmon | F14: 16.1 | G14: 337025 | H14: 33.83 | I14: 1 kg | J14: 9961.7 | K14: 17 | L14: KG | M14: South Wind | N14: 0 | O14: 46010 | P14: 46017 | Q14: 7 | R14: 3 | S14: 0.25 | T14: 46018 | U14: 8 | V14: 27 | W14: 0 | X14: 0 | Y14: 16 | Z14: 0
A15: =IFERROR(VLOOKUP(InteliPar[[#This Row],[Nombre de Articulo]],Productos[],4,FALSE),"00 Falta Info") -> 0 | B15: =IFERROR(VLOOKUP(InteliPar[[#This Row],[Nombre de Articulo]],Productos[],3,FALSE),"00 Falta Info") -> Mariscos | C15: =IFERROR(VLOOKUP(InteliPar[[#This Row],[Nombre de Articulo]],Productos[],2,FALSE),"00 Falta Info") -> Mariscos | D15: 46024 | E15: Almejas | F15: 12.3 | G15: 86907 | H15: 28.56 | I15: 1 kg | J15: 3043.07 | K15: -0.8 | L15: KG | M15: Comercial Valenzuela CompaÃ±ia Limitada | N15: 15 | O15: 46010 | P15: 46017 | Q15: 7 | R15: 3 | S15: 0.25 | T15: 46018 | U15: 8 | V15: -2 | W15: 0 | X15: 0 | Y15: -286 | Z15: 0
A16: =IFERROR(VLOOKUP(InteliPar[[#This Row],[Nombre de Articulo]],Productos[],4,FALSE),"00 Falta Info") -> 0 | B16: =IFERROR(VLOOKUP(InteliPar[[#This Row],[Nombre de Articulo]],Productos[],3,FALSE),"00 Falta Info") -> Mariscos | C16: =IFERROR(VLOOKUP(InteliPar[[#This Row],[Nombre de Articulo]],Productos[],2,FALSE),"00 Falta Info") -> Mariscos | D16: 46024 | E16: Camaron 36/40 Sin cascara | F16: 8.6 | G16: 141516 | H16: 18.68 | I16: 1 kg | J16: 7573.93 | K16: 17.6 | L16: KG | M16: South Wind | N16: 0 | O16: 46010 | P16: 46017 | Q16: 7 | R16: 3 | S16: 0.25 | T16: 46018 | U16: 8 | V16: 28 | W16: 10 | X16: 75739.3 | Y16: 8 | Z16: 0
A17: =IFERROR(VLOOKUP(InteliPar[[#This Row],[Nombre de Articulo]],Productos[],4,FALSE),"00 Falta Info") -> 0 | B17: =IFERROR(VLOOKUP(InteliPar[[#This Row],[Nombre de Articulo]],Productos[],3,FALSE),"00 Falta Info") -> Mariscos | C17: =IFERROR(VLOOKUP(InteliPar[[#This Row],[Nombre de Articulo]],Productos[],2,FALSE),"00 Falta Info") -> Mariscos | D17: 46024 | E17: Langostino | F17: 7.8 | G17: 298157 | H17: 23.77 | I17: 1 kg | J17: 12546 | K17: 29.7 | L17: KG | M17: South Wind | N17: 12 | O17: 46010 | P17: 46017 | Q17: 7 | R17: 3 | S17: 0.25 | T17: 46018 | U17: 8 | V17: 47 | W17: 24 | X17: 301104 | Y17: 6 | Z17: 0
A18: =IFERROR(VLOOKUP(InteliPar[[#This Row],[Nombre de Articulo]],Productos[],4,FALSE),"00 Falta Info") -> 0 | B18: =IFERROR(VLOOKUP(InteliPar[[#This Row],[Nombre de Articulo]],Productos[],3,FALSE),"00 Falta Info") -> Mariscos | C18: =IFERROR(VLOOKUP(InteliPar[[#This Row],[Nombre de Articulo]],Productos[],2,FALSE),"00 Falta Info") -> Mariscos | D18: 46024 | E18: Locos | F18: 9.2 | G18: 754364 | H18: 32.17 | I18: 1 kg | J18: 23450.34 | K18: 9.2 | L18: KG | M18: Aldo Luis ZuÃ±iga Ayala | N18: 5 | O18: 46010 | P18: 46017 | Q18: 7 | R18: 3 | S18: 0.25 | T18: 46018 | U18: 8 | V18: 15 | W18: 0 | X18: 0 | Y18: 28 | Z18: 283162.86
A19: =IFERROR(VLOOKUP(InteliPar[[#This Row],[Nombre de Articulo]],Productos[],4,FALSE),"00 Falta Info") -> 0 | B19: =IFERROR(VLOOKUP(InteliPar[[#This Row],[Nombre de Articulo]],Productos[],3,FALSE),"00 Falta Info") -> Mariscos | C19: =IFERROR(VLOOKUP(InteliPar[[#This Row],[Nombre de Articulo]],Productos[],2,FALSE),"00 Falta Info") -> Mariscos | D19: 46024 | E19: Ostion | F19: 3.9 | G19: 328300 | H19: 21.46 | I19: 1 kg | J19: 15300 | K19: 6.2 | L19: KG | M19: South Wind | N19: 0 | O19: 46010 | P19: 46017 | Q19: 7 | R19: 3 | S19: 0.25 | T19: 46018 | U19: 8 | V19: 10 | W19: 0 | X19: 0 | Y19: 28 | Z19: 124503.75
A20: =IFERROR(VLOOKUP(InteliPar[[#This Row],[Nombre de Articulo]],Productos[],4,FALSE),"00 Falta Info") -> 0 | B20: =IFERROR(VLOOKUP(InteliPar[[#This Row],[Nombre de Articulo]],Productos[],3,FALSE),"00 Falta Info") -> Mariscos | C20: =IFERROR(VLOOKUP(InteliPar[[#This Row],[Nombre de Articulo]],Productos[],2,FALSE),"00 Falta Info") -> Mariscos | D20: 46024 | E20: Ostion sin concha | G20: 44700 | H20: 3 | I20: 1 kg | J20: 14900 | K20: 2.4 | L20: KG | M20: South Wind | N20: 0 | O20: 46010 | P20: 46017 | Q20: 7 | R20: 3 | S20: 0.25 | T20: 46018 | U20: 8 | V20: 4 | W20: 1 | X20: 14900 | Y20: 10 | Z20: 0
A21: =IFERROR(VLOOKUP(InteliPar[[#This Row],[Nombre de Articulo]],Productos[],4,FALSE),"00 Falta Info") -> 0 | B21: =IFERROR(VLOOKUP(InteliPar[[#This Row],[Nombre de Articulo]],Productos[],3,FALSE),"00 Falta Info") -> Mariscos | C21: =IFERROR(VLOOKUP(InteliPar[[#This Row],[Nombre de Articulo]],Productos[],2,FALSE),"00 Falta Info") -> Mariscos | D21: 46024 | E21: Ostras | F21: 10.3 | G21: 18398.6 | H21: 1.27 | I21: 1 kg | J21: 14495.83 | K21: 1.6 | L21: KG | M21: Comercial Valenzuela CompaÃ±ia Limitada | N21: 0 | O21: 46010 | P21: 46017 | Q21: 7 | R21: 3 | S21: 0.25 | T21: 46018 | U21: 8 | V21: 3 | W21: 2 | X21: 28991.66 | Y21: 6 | Z21: 0
A22: =IFERROR(VLOOKUP(InteliPar[[#This Row],[Nombre de Articulo]],Productos[],4,FALSE),"00 Falta Info") -> 0 | B22: =IFERROR(VLOOKUP(InteliPar[[#This Row],[Nombre de Articulo]],Productos[],3,FALSE),"00 Falta Info") -> Mariscos | C22: =IFERROR(VLOOKUP(InteliPar[[#This Row],[Nombre de Articulo]],Productos[],2,FALSE),"00 Falta Info") -> Mariscos | D22: 46024 | E22: Pulpo | F22: 16.7 | G22: 118055 | H22: 12.76 | I22: 1 kg | J22: 9250.65 | K22: 23.1 | L22: KG | M22: Aldo Luis ZuÃ±iga Ayala | N22: 0 | O22: 46010 | P22: 46017 | Q22: 7 | R22: 3 | S22: 0.25 | T22: 46018 | U22: 8 | V22: 37 | W22: 25 | X22: 231266.25 | Y22: 4 | Z22: 0
A23: =IFERROR(VLOOKUP(InteliPar[[#This Row],[Nombre de Articulo]],Productos[],4,FALSE),"00 Falta Info") -> 0 | B23: =IFERROR(VLOOKUP(InteliPar[[#This Row],[Nombre de Articulo]],Productos[],3,FALSE),"00 Falta Info") -> Embutidos | C23: =IFERROR(VLOOKUP(InteliPar[[#This Row],[Nombre de Articulo]],Productos[],2,FALSE),"00 Falta Info") -> Embutidos | D23: 46024 | E23: Jamon Serrano | F23: 5.1 | G23: 194009 | H23: 8.44 | I23: 1 kg | J23: 22980 | K23: 7.8 | L23: KG | M23: Delicasei SpA | N23: 6 | O23: 46010 | P23: 46017 | Q23: 7 | R23: 3 | S23: 0.25 | T23: 46018 | U23: 8 | V23: 13 | W23: 5 | X23: 114900 | Y23: 9 | Z23: 0
A24: =IFERROR(VLOOKUP(InteliPar[[#This Row],[Nombre de Articulo]],Productos[],4,FALSE),"00 Falta Info") -> 0 | B24: =IFERROR(VLOOKUP(InteliPar[[#This Row],[Nombre de Articulo]],Productos[],3,FALSE),"00 Falta Info") -> Embutidos | C24: =IFERROR(VLOOKUP(InteliPar[[#This Row],[Nombre de Articulo]],Productos[],2,FALSE),"00 Falta Info") -> Embutidos | D24: 46024 | E24: Pepperoni | F24: 1.7 | G24: 70062.2 | H24: 6.74 | I24: 1 kg | J24: 10387.28 | K24: 2.2 | L24: KG | M24: Importadora y Alimentos ICB Food Service Ltda | N24: 0 | O24: 46010 | P24: 46017 | Q24: 7 | R24: 3 | S24: 0.25 | T24: 46018 | U24: 8 | V24: 4 | W24: 0 | X24: 0 | Y24: 25 | Z24: 21423.765
A25: =IFERROR(VLOOKUP(InteliPar[[#This Row],[Nombre de Articulo]],Productos[],4,FALSE),"00 Falta Info") -> 0 | B25: =IFERROR(VLOOKUP(InteliPar[[#This Row],[Nombre de Articulo]],Productos[],3,FALSE),"00 Falta Info") -> Lacteos | C25: =IFERROR(VLOOKUP(InteliPar[[#This Row],[Nombre de Articulo]],Productos[],2,FALSE),"00 Falta Info") -> Quesos | D25: 46024 | E25: Burrata | F25: 51 | G25: 599406 | H25: 143 | I25: 125 g | J25: 4191.65 | K25: 57.9 | L25: PIECE | M25: Qifood Spa | N25: 0 | O25: 46010 | P25: 46017 | Q25: 7 | R25: 3 | S25: 0.25 | T25: 46018 | U25: 8 | V25: 91 | W25: 0 | X25: 0 | Y25: 20 | Z25: 75842.667
A26: =IFERROR(VLOOKUP(InteliPar[[#This Row],[Nombre de Articulo]],Productos[],4,FALSE),"00 Falta Info") -> 0 | B26: =IFERROR(VLOOKUP(InteliPar[[#This Row],[Nombre de Articulo]],Productos[],3,FALSE),"00 Falta Info") -> Lacteos | C26: =IFERROR(VLOOKUP(InteliPar[[#This Row],[Nombre de Articulo]],Productos[],2,FALSE),"00 Falta Info") -> Quesos | D26: 46024 | E26: Mascarpone | F26: -9 | H26: 9 | I26: 1 kg | K26: -9 | L26: KG | M26: Qifood Spa | N26: 0 | O26: 46010 | P26: 46017 | Q26: 7 | R26: 3 | S26: 0.25 | T26: 46018 | U26: 8 | V26: -15 | W26: 0 | X26: 0 | Y26: -8 | Z26: 0
A27: =IFERROR(VLOOKUP(InteliPar[[#This Row],[Nombre de Articulo]],Productos[],4,FALSE),"00 Falta Info") -> 0 | B27: =IFERROR(VLOOKUP(InteliPar[[#This Row],[Nombre de Articulo]],Productos[],3,FALSE),"00 Falta Info") -> Lacteos | C27: =IFERROR(VLOOKUP(InteliPar[[#This Row],[Nombre de Articulo]],Productos[],2,FALSE),"00 Falta Info") -> Quesos | D27: 46024 | E27: Mozzarella Fior Di Latte | F27: 34.6 | G27: 542664 | H27: 44.79 | I27: 1 kg | J27: 12116.61 | K27: 40.6 | L27: KG | M27: Qifood Spa | N27: 50 | O27: 46010 | P27: 46017 | Q27: 7 | R27: 3 | S27: 0.25 | T27: 46018 | U27: 8 | V27: 64 | W27: 20 | X27: 242332.2 | Y27: 9 | Z27: 0
A28: =IFERROR(VLOOKUP(InteliPar[[#This Row],[Nombre de Articulo]],Productos[],4,FALSE),"00 Falta Info") -> 0 | B28: =IFERROR(VLOOKUP(InteliPar[[#This Row],[Nombre de Articulo]],Productos[],3,FALSE),"00 Falta Info") -> Lacteos | C28: =IFERROR(VLOOKUP(InteliPar[[#This Row],[Nombre de Articulo]],Productos[],2,FALSE),"00 Falta Info") -> Quesos | D28: 46024 | E28: Parmesano | F28: 2.5 | G28: 152464 | H28: 11.74 | I28: 1 kg | J28: 12990 | K28: 3.2 | L28: KG | M28: Delicasei SpA | N28: 5 | O28: 46010 | P28: 46017 | Q28: 7 | R28: 3 | S28: 0.25 | T28: 46018 | U28: 8 | V28: 5 | W28: 0 | X28: 0 | Y28: 29 | Z28: 59754
A29: =IFERROR(VLOOKUP(InteliPar[[#This Row],[Nombre de Articulo]],Productos[],4,FALSE),"00 Falta Info") -> 0 | B29: =IFERROR(VLOOKUP(InteliPar[[#This Row],[Nombre de Articulo]],Productos[],3,FALSE),"00 Falta Info") -> Lacteos | C29: =IFERROR(VLOOKUP(InteliPar[[#This Row],[Nombre de Articulo]],Productos[],2,FALSE),"00 Falta Info") -> Quesos | D29: 46024 | E29: Provoleta | F29: 6.4 | G29: 103862 | H29: 7.59 | I29: 1 kg | J29: 13690 | K29: 7.2 | L29: KG | M29: Delicasei SpA | N29: 0 | O29: 46010 | P29: 46017 | Q29: 7 | R29: 3 | S29: 0.25 | T29: 46018 | U29: 8 | V29: 12 | W29: 5 | X29: 68450 | Y29: 8 | Z29: 0
A30: =IFERROR(VLOOKUP(InteliPar[[#This Row],[Nombre de Articulo]],Productos[],4,FALSE),"00 Falta Info") -> 0 | B30: =IFERROR(VLOOKUP(InteliPar[[#This Row],[Nombre de Articulo]],Productos[],3,FALSE),"00 Falta Info") -> Lacteos | C30: =IFERROR(VLOOKUP(InteliPar[[#This Row],[Nombre de Articulo]],Productos[],2,FALSE),"00 Falta Info") -> Quesos | D30: 46024 | E30: Queso Azul | F30: 1.6 | G30: 15304.7 | H30: 1.09 | I30: 1 kg | J30: 13989.7 | K30: 1.6 | L30: KG | M30: Delicasei SpA | N30: 0 | O30: 46010 | P30: 46017 | Q30: 7 | R30: 3 | S30: 0.25 | T30: 46018 | U30: 8 | V30: 3 | W30: 2 | X30: 27979.4 | Y30: 5 | Z30: 0
A31: =IFERROR(VLOOKUP(InteliPar[[#This Row],[Nombre de Articulo]],Productos[],4,FALSE),"00 Falta Info") -> 0 | B31: =IFERROR(VLOOKUP(InteliPar[[#This Row],[Nombre de Articulo]],Productos[],3,FALSE),"00 Falta Info") -> Lacteos | C31: =IFERROR(VLOOKUP(InteliPar[[#This Row],[Nombre de Articulo]],Productos[],2,FALSE),"00 Falta Info") -> Quesos | D31: 46024 | E31: Queso Brie | F31: 1.2 | G31: 112734 | H31: 4.45 | I31: 1 kg | J31: 25356.34 | K31: 1.2 | L31: KG | M31: Bastien | N31: 1.1 | O31: 46010 | P31: 46017 | Q31: 7 | R31: 3 | S31: 0.25 | T31: 46018 | U31: 8 | V31: 2 | W31: 0 | X31: 0 | Y31: 30 | Z31: 47543.137
A32: =IFERROR(VLOOKUP(InteliPar[[#This Row],[Nombre de Articulo]],Productos[],4,FALSE),"00 Falta Info") -> 0 | B32: =IFERROR(VLOOKUP(InteliPar[[#This Row],[Nombre de Articulo]],Productos[],3,FALSE),"00 Falta Info") -> Lacteos | C32: =IFERROR(VLOOKUP(InteliPar[[#This Row],[Nombre de Articulo]],Productos[],2,FALSE),"00 Falta Info") -> Quesos | D32: 46024 | E32: Queso Crema | F32: 5.4 | G32: 90159.6 | H32: 8.85 | I32: 1 kg | J32: 10188.08 | K32: 6.7 | L32: KG | M32: Delicasei SpA | N32: 0 | O32: 46010 | P32: 46017 | Q32: 7 | R32: 3 | S32: 0.25 | T32: 46018 | U32: 8 | V32: 11 | W32: 3 | X32: 30564.24 | Y32: 11 | Z32: 0
A33: =IFERROR(VLOOKUP(InteliPar[[#This Row],[Nombre de Articulo]],Productos[],4,FALSE),"00 Falta Info") -> 0 | B33: =IFERROR(VLOOKUP(InteliPar[[#This Row],[Nombre de Articulo]],Productos[],3,FALSE),"00 Falta Info") -> Lacteos | C33: =IFERROR(VLOOKUP(InteliPar[[#This Row],[Nombre de Articulo]],Productos[],2,FALSE),"00 Falta Info") -> Quesos | D33: 46024 | E33: Queso de Cabra | F33: 5.2 | G33: 32373.8 | H33: 1.78 | I33: 1 kg | J33: 18156.92 | K33: 5.2 | L33: KG | M33: Bastien | N33: 0 | O33: 46010 | P33: 46017 | Q33: 7 | R33: 3 | S33: 0.25 | T33: 46018 | U33: 8 | V33: 9 | W33: 8 | X33: 145255.36 | Y33: 3 | Z33: 0
A34: =IFERROR(VLOOKUP(InteliPar[[#This Row],[Nombre de Articulo]],Productos[],4,FALSE),"00 Falta Info") -> 0 | B34: =IFERROR(VLOOKUP(InteliPar[[#This Row],[Nombre de Articulo]],Productos[],3,FALSE),"00 Falta Info") -> Abarrotes | C34: =IFERROR(VLOOKUP(InteliPar[[#This Row],[Nombre de Articulo]],Productos[],2,FALSE),"00 Falta Info") -> Chocolate | D34: 46024 | E34: Belcolade Bitter | F34: -3.3 | H34: 19.26 | I34: 1 kg | K34: 1.7 | L34: KG | M34: Bastien | N34: 0 | O34: 46010 | P34: 46017 | Q34: 7 | R34: 3 | S34: 0.25 | T34: 46018 | U34: 8 | V34: 3 | W34: 0 | X34: 0 | Y34: 91 | Z34: 0
A35: =IFERROR(VLOOKUP(InteliPar[[#This Row],[Nombre de Articulo]],Productos[],4,FALSE),"00 Falta Info") -> 0 | B35: =IFERROR(VLOOKUP(InteliPar[[#This Row],[Nombre de Articulo]],Productos[],3,FALSE),"00 Falta Info") -> Abarrotes | C35: =IFERROR(VLOOKUP(InteliPar[[#This Row],[Nombre de Articulo]],Productos[],2,FALSE),"00 Falta Info") -> Chocolate | D35: 46024 | E35: Belcolade Blanco | F35: -0.3 | G35: 84419.2 | H35: 8.55 | I35: 1 kg | J35: 9876.29 | K35: 1.2 | L35: KG | M35: Bastien | N35: 0 | O35: 46010 | P35: 46017 | Q35: 7 | R35: 3 | S35: 0.25 | T35: 46018 | U35: 8 | V35: 2 | W35: 0 | X35: 0 | Y35: 57 | Z35: 58517.018
A36: =IFERROR(VLOOKUP(InteliPar[[#This Row],[Nombre de Articulo]],Productos[],4,FALSE),"00 Falta Info") -> 0 | B36: =IFERROR(VLOOKUP(InteliPar[[#This Row],[Nombre de Articulo]],Productos[],3,FALSE),"00 Falta Info") -> Abarrotes | C36: =IFERROR(VLOOKUP(InteliPar[[#This Row],[Nombre de Articulo]],Productos[],2,FALSE),"00 Falta Info") -> Chocolate | D36: 46024 | E36: Belcolade De Leche | F36: -1.3 | H36: 10.31 | I36: 1 kg | K36: 0.3 | L36: KG | M36: Bastien | N36: 0 | O36: 46010 | P36: 46017 | Q36: 7 | R36: 3 | S36: 0.25 | T36: 46018 | U36: 8 | V36: 1 | W36: 0 | X36: 0 | Y36: 275 | Z36: 0
A37: =IFERROR(VLOOKUP(InteliPar[[#This Row],[Nombre de Articulo]],Productos[],4,FALSE),"00 Falta Info") -> 0 | B37: =IFERROR(VLOOKUP(InteliPar[[#This Row],[Nombre de Articulo]],Productos[],3,FALSE),"00 Falta Info") -> Abarrotes | C37: =IFERROR(VLOOKUP(InteliPar[[#This Row],[Nombre de Articulo]],Productos[],2,FALSE),"00 Falta Info") -> Aceite | D37: 46024 | E37: Aceite Vegetal 900ml | F37: 10 | G37: 41494.7 | H37: 26 | I37: 1 | J37: 1595.95 | K37: 10 | L37: BOTTLE | M37: Bastien | N37: 36 | O37: 46010 | P37: 46017 | Q37: 7 | R37: 3 | S37: 0.25 | T37: 46018 | U37: 8 | V37: 16 | W37: 0 | X37: 0 | Y37: 21 | Z37: 6982.2812
A38: =IFERROR(VLOOKUP(InteliPar[[#This Row],[Nombre de Articulo]],Productos[],4,FALSE),"00 Falta Info") -> 0 | B38: =IFERROR(VLOOKUP(InteliPar[[#This Row],[Nombre de Articulo]],Productos[],3,FALSE),"00 Falta Info") -> Verduras | C38: =IFERROR(VLOOKUP(InteliPar[[#This Row],[Nombre de Articulo]],Productos[],2,FALSE),"00 Falta Info") -> Champiñon | D38: 46024 | E38: ChampiÃ±on Ostra | F38: 1.3 | G38: 50834.5 | H38: 2.68 | I38: 1 kg | J38: 19000 | K38: 2.4 | L38: KG | M38: Transyver SPA | N38: 2.8 | O38: 46010 | P38: 46017 | Q38: 7 | R38: 3 | S38: 0.25 | T38: 46018 | U38: 8 | V38: 4 | W38: 2 | X38: 38000 | Y38: 9 | Z38: 0
A39: =IFERROR(VLOOKUP(InteliPar[[#This Row],[Nombre de Articulo]],Productos[],4,FALSE),"00 Falta Info") -> 0 | B39: =IFERROR(VLOOKUP(InteliPar[[#This Row],[Nombre de Articulo]],Productos[],3,FALSE),"00 Falta Info") -> Verduras | C39: =IFERROR(VLOOKUP(InteliPar[[#This Row],[Nombre de Articulo]],Productos[],2,FALSE),"00 Falta Info") -> Champiñon | D39: 46024 | E39: ChampiÃ±on Portobello | F39: 0.3 | G39: 13513.5 | H39: 1.04 | I39: 1 kg | J39: 13000 | K39: 1.3 | L39: KG | M39: Transyver SPA | N39: 0 | O39: 46010 | P39: 46017 | Q39: 7 | R39: 3 | S39: 0.25 | T39: 46018 | U39: 8 | V39: 3 | W39: 2 | X39: 26000 | Y39: 6 | Z39: 0
A40: =IFERROR(VLOOKUP(InteliPar[[#This Row],[Nombre de Articulo]],Productos[],4,FALSE),"00 Falta Info") -> 0 | B40: =IFERROR(VLOOKUP(InteliPar[[#This Row],[Nombre de Articulo]],Productos[],3,FALSE),"00 Falta Info") -> Verduras | C40: =IFERROR(VLOOKUP(InteliPar[[#This Row],[Nombre de Articulo]],Productos[],2,FALSE),"00 Falta Info") -> Palta | D40: 46024 | E40: Palta Hass | F40: 21.5 | G40: 56148.7 | H40: 12.48 | I40: 1 kg | J40: 4500 | K40: 25.3 | L40: KG | M40: Transyver SPA | N40: 26.3 | O40: 46010 | P40: 46017 | Q40: 7 | R40: 3 | S40: 0.25 | T40: 46018 | U40: 8 | V40: 40 | W40: 28 | X40: 126000 | Y40: 4 | Z40: 0
...

Sheet Pivot
A1: Ahorro/faltantes inventario ($)
B2: Column Labels
B3: Postres | C3: Verduras | D3: Lacteos | E3: Embutidos | F3: Mariscos | G3: Pescado | H3: Carnes | I3: Aves | J3: Abarrotes | K3: Colación
A4: Suma de Diferencia (Costo) | B4: 15646 | C4: -35011.69 | D4: 34824.43 | E4: 9292.24 | F4: 8935.68 | G4: -40215.08 | H4: -3654.88 | I4: 20030.2 | J4: -55563.9 | K4: -47296.13
K6: Fecha del periodo
A7: Suma de Ahorro | B7: =+SUMIF($B$4:$J$4,">"&0,$B$4:$J$4) -> 88728.55 | K7: Fecha Inicial | L7: Fecha
A8: Suma de Faltante | B8: =+SUMIF($B$4:$J$4,"<"&0,$B$4:$J$4) -> -134445.55 | K8: 46177 | L8: 46183
K9: Grand Total
A10: Suma de Desperdicio (Costo)
A11: 22974.7
A13: Desempeño de los 10 productos con mayor uso ($)
A14: Row Labels | B14: Suma de Usado (Costo) | C14: Suma de Diferencia (Costo) | D14: Suma de % Diferencia | E14: % Costo Real
A15: Entra��a | B15: 1123500 | C15: -10700 | D15: -0.01 | E15: 0.39992509
A16: Mozzarella Fior Di Latte | B16: 382743.95 | C16: 413.95 | D16: 0.001 | E16: 0.18794092
A17: Corvina | B17: 241218.09 | C17: -27279.16 | D17: -0.115 | E17: 0.93324946
A18: Ojo de Bife | B18: 233654.38 | C18: -14327.71 | D18: -0.061 | E18: 0.38176635
A19: Locos | B19: 177921.32 | C19: 1287.03 | D19: 0.007 | E19: 0.49064588
A20: Filete | B20: 173521.12 | C20: 15372.83 | D20: 0.089 | E20: 0.21958165
A21: Salmon | B21: 125836.29 | C21: -9187.82 | D21: -0.073 | E21: 0.25034854
A22: Filete Medallon | B22: 119000 | C22: 0 | D22: 0 | E22: 0.41941133
A23: Pulpo | B23: 108811.99 | C23: -16852.42 | D23: -0.154 | E23: 0.31752862
A24: Burrata | B24: 106061.05 | C24: 0 | D24: 0 | E24: 0.40795619
A27: Compra Realizada vs Sugerida por familia
A28: Row Labels | B28: Compra Sugerida | C28: Compra Realizada
A29: Postres | B29: 237482 | C29: 114174
A30: Verduras | B30: 60016.8 | C30: 318762
A31: Lacteos | B31: 393802 | C31: 519750.2
A32: Embutidos | B32: 9952.67 | C32: 115500
A33: Mariscos | B33: 102688 | C33: 767376
A34: Pescado | B34: 860783 | C34: 388493
A35: Carnes | B35: 410332.76 | C35: 1217000
A36: Aves | B36: 0 | C36: 0
A37: Abarrotes | B37: 75852 | C37: 84672
A38: Colación | B38: 0 | C38: 93003.5
A39: Grand Total | B39: 2150909.2 | C39: 3618730.7

Sheet Reporte
E5: Bardot | L5: Periodo | S5: =+E5 -> Bardot | Z5: Periodo
L6: del: | M6: =+Pivot!K8 -> 46177 | Z6: del: | AA6: =+M6 -> 46177
L7: al: | M7: =+Pivot!L8 -> 46183 | Z7: al: | AA7: =+M7 -> 46183
B59: Desempeño de los 10 productos con mayor uso ($)
B61: Productos | F61: Usado ($) | H61: Ahorro / Faltante al costo | J61: % de Ahorro / Faltante | L61: Costo Real
B62: =+Pivot!A15 -> Entra��a | F62: =+Pivot!B15 -> 1123500 | H62: =+Pivot!C15 -> -10700 | J62: =+Pivot!D15 -> -0.01 | L62: =+Pivot!E15 -> 0.39992509
B63: =+Pivot!A16 -> Mozzarella Fior Di Latte | F63: =+Pivot!B16 -> 382743.95 | H63: =+Pivot!C16 -> 413.95 | J63: =+Pivot!D16 -> 0.001 | L63: =+Pivot!E16 -> 0.18794092
B64: =+Pivot!A17 -> Corvina | F64: =+Pivot!B17 -> 241218.09 | H64: =+Pivot!C17 -> -27279.16 | J64: =+Pivot!D17 -> -0.115 | L64: =+Pivot!E17 -> 0.93324946
B65: =+Pivot!A18 -> Ojo de Bife | F65: =+Pivot!B18 -> 233654.38 | H65: =+Pivot!C18 -> -14327.71 | J65: =+Pivot!D18 -> -0.061 | L65: =+Pivot!E18 -> 0.38176635
B66: =+Pivot!A19 -> Locos | F66: =+Pivot!B19 -> 177921.32 | H66: =+Pivot!C19 -> 1287.03 | J66: =+Pivot!D19 -> 0.007 | L66: =+Pivot!E19 -> 0.49064588
B67: =+Pivot!A20 -> Filete | F67: =+Pivot!B20 -> 173521.12 | H67: =+Pivot!C20 -> 15372.83 | J67: =+Pivot!D20 -> 0.089 | L67: =+Pivot!E20 -> 0.21958165
B68: =+Pivot!A21 -> Salmon | F68: =+Pivot!B21 -> 125836.29 | H68: =+Pivot!C21 -> -9187.82 | J68: =+Pivot!D21 -> -0.073 | L68: =+Pivot!E21 -> 0.25034854
B69: =+Pivot!A22 -> Filete Medallon | F69: =+Pivot!B22 -> 119000 | H69: =+Pivot!C22 -> 0 | J69: =+Pivot!D22 -> 0 | L69: =+Pivot!E22 -> 0.41941133
B70: =+Pivot!A23 -> Pulpo | F70: =+Pivot!B23 -> 108811.99 | H70: =+Pivot!C23 -> -16852.42 | J70: =+Pivot!D23 -> -0.154 | L70: =+Pivot!E23 -> 0.31752862
B71: =+Pivot!A24 -> Burrata | F71: =+Pivot!B24 -> 106061.05 | H71: =+Pivot!C24 -> 0 | J71: =+Pivot!D24 -> 0 | L71: =+Pivot!E24 -> 0.40795619
